<?xml version="1.0"?>

<robot name="a0912" xmlns:xacro="http://www.ros.org/wiki/xacro">

	<!-- I did some modifications concerning the original file-->
	<!-- The  damping and friction where added in each joint-->
	<!-- The created addded, and called the gazebo_config_control.xacro -->
	
	
	<xacro:include filename="$(find my_doosan_pkg)/description/xacro/macro.gazebo_config_control.xacro" />
	<xacro:include filename="$(find my_doosan_pkg)/description/xacro/macro.transmission.xacro" />
	<xacro:include filename="$(find my_doosan_pkg)/description/xacro/macro.internal_config.xacro" />


	<xacro:macro name="a0912" params="namespace">
		
		<!-- Base -->
		<link name="base_0">
			<inertial>
				<mass value="3.635"/>
				<origin xyz="4e-06   -0.001016     0.08181"/>
				<inertia ixx="0.02216" ixy="5.8001e-06" ixz="6.1941e-06" iyy="0.024835"
					iyz="-5.3034e-05"
					izz="0.021063"/>
			</inertial>
			<visual>
				<origin rpy="0 0 0" xyz="0 0 0" />
				<geometry>
					<mesh filename="file:///$(find my_doosan_pkg)/description/meshes/a0912_blue/A0912_0_0.dae" scale="0.001 0.001 0.001" />
				</geometry>
			</visual>
			<collision>
        		<geometry>
					<mesh filename="file:///$(find my_doosan_pkg)/description/meshes/a0912_blue/A0912_0_0.dae" scale="0.001 0.001 0.001" />
        		</geometry>
      		</collision>
		</link>


		<!-- joint 1 -->
		<joint name="joint1" type="revolute">
			<parent link="base_0" />
			<child link="link1" />
			<origin rpy="0 0 0" xyz="0 0 0.195" />
			<axis xyz="0 0 1" />
			<limit effort="411" lower="-6.2832" upper="6.2832" velocity="3.1416"/>
			<dynamics damping="60.0" friction="4.0" />
		</joint>


		<!-- Link 1 -->
		<link name="link1">
			<inertial>
				<mass value="7.863"/>
				<origin xyz="4.4e-05    0.029982    -0.01112"/>
				<inertia ixx="0.045839" ixy="1.2759e-05" ixz="-3.6168e-05" iyy="0.032913"
					iyz="-0.0029965"
					izz="0.044399"/>
			</inertial>
            <collision>
                <geometry>
                    <cylinder radius="0.08" length="0.2"/>
                </geometry>
            </collision>
			<visual>
				<origin rpy="0 0 0" xyz="0 0 0" />
				<geometry>
					<mesh filename="file:///$(find my_doosan_pkg)/description/meshes/a0912_blue/A0912_1_0.dae" scale="0.001 0.001 0.001" />
				</geometry>
			</visual>
            <visual>
				<origin rpy="0 0 0" xyz="0 0 0" />
				<geometry>
					<mesh filename="file:///$(find my_doosan_pkg)/description/meshes/a0912_blue/A0912_1_1.dae" scale="0.001 0.001 0.001" />
				</geometry>
			</visual>
            <visual>
				<origin rpy="0 0 0" xyz="0 0 0" />
				<geometry>
					<mesh filename="file:///$(find my_doosan_pkg)/description/meshes/a0912_blue/A0912_1_2.dae" scale="0.001 0.001 0.001" />
				</geometry>
			</visual>
		</link>


		<!-- joint2 -->
		<joint name="joint2" type="revolute">
			<parent link="link1" />
			<child link="link2" />
			<origin rpy="0 -1.571 -1.571" xyz="0 0.039 0" />
			<axis xyz="0 0 1" />
			<limit effort="411" lower="-6.2832" upper="6.2832" velocity="3.1416"/>
			<dynamics damping="50.0" friction="3.0" />		
		</joint>
		

		<!-- Link 2 -->
		<link name="link2">
			<inertial>
				<mass value="10.985"/>
				<origin xyz="0.19748    0.001426     0.13191"/>
				<inertia ixx="0.04446" ixy="-0.0049948" ixz="-0.010992" iyy="0.67642" iyz="-2.8483e-05"
					izz="0.67428"/>
			</inertial>
            <collision>
                <origin rpy="0 -1.571 0" xyz="0.3 0 0.1525" />
                <geometry>
                    <cylinder radius="0.08" length="0.6"/>
                </geometry>
            </collision>
			<visual>
				<origin rpy="0 0 0" xyz="0 0 0" />
				<geometry>
					<mesh filename="file:///$(find my_doosan_pkg)/description/meshes/a0912_blue/A0912_2_0.dae" scale="0.001 0.001 0.001" />
				</geometry>
			</visual>
			<visual>
				<origin rpy="0 0 0" xyz="0 0 0" />
				<geometry>
					<mesh filename="file:///$(find my_doosan_pkg)/description/meshes/a0912_blue/A0912_2_1.dae" scale="0.001 0.001 0.001" />
				</geometry>
			</visual>
			<visual>
				<origin rpy="0 0 0" xyz="0 0 0" />
				<geometry>
					<mesh filename="file:///$(find my_doosan_pkg)/description/meshes/a0912_blue/A0912_2_2.dae" scale="0.001 0.001 0.001" />
				</geometry>
			</visual>
		</link>


		<!-- joint3 -->
		<joint name="joint3" type="revolute">
			<parent link="link2" />
			<child link="link3" />
			<origin rpy="0 0 1.571" xyz="0.56 0 0" />
			<axis xyz="0 0 1" />
			<limit effort="194" lower="-2.7925" upper="2.7925" velocity="3.1416"/>
			<dynamics damping="40.0" friction="2.0"/>
		</joint>
		

		<!-- Link 3 -->
		<link name="link3">
			<inertial>
				<mass value="2.881"/>
				<origin xyz="8.5e-05   -0.002513    0.032058"/>
				<inertia ixx="0.012756" ixy="-5.4257e-06" ixz="1.6402e-05" iyy="0.011416"
					iyz="-0.0001989"
					izz="0.0080652"/>
			</inertial>
			<visual>
				<origin rpy="0 0 0" xyz="0 0 0" />
				<geometry>
					<mesh filename="file:///$(find my_doosan_pkg)/description/meshes/a0912_blue/A0912_3_0.dae" scale="0.001 0.001 0.001" />
				</geometry>
			</visual>
            <visual>
				<origin rpy="0 0 0" xyz="0 0 0" />
				<geometry>
					<mesh filename="file:///$(find my_doosan_pkg)/description/meshes/a0912_blue/A0912_3_1.dae" scale="0.001 0.001 0.001" />
				</geometry>
			</visual>
		</link>


		<!-- joint4 -->
		<joint name="joint4" type="revolute">
			<parent link="link3" />
			<child link="link4" />
			<origin rpy="1.571 0 0" xyz="0 -0.516 0" />
			<axis xyz="0 0 1" />
			<limit effort="50" lower="-6.2832" upper="6.2832" velocity="6.2832"/>
			<dynamics damping="20.0" friction="1.0" />
		</joint>


		<!-- Link 4 -->
		<link name="link4">
			<inertial>
				<mass value="3.273"/>
				<origin xyz="-9.6e-05    0.085314    -0.13975"/>
				<inertia ixx="0.12246" ixy="2.3905e-05" ixz="2.5022e-05" iyy="0.11307" iyz="-0.027995"
					izz="0.017186"/>
			</inertial>
            <collision>
                <origin rpy="-0.46 0 0" xyz="0 0.075 -0.2" />
                <geometry>
                    <cylinder radius="0.05" length="0.4"/>
                </geometry>
            </collision>
			<visual>
				<origin rpy="0 0 0" xyz="0 0 0" />
				<geometry>
					<mesh filename="file:///$(find my_doosan_pkg)/description/meshes/a0912_blue/A0912_4_0.dae" scale="0.001 0.001 0.001" />
				</geometry>
			</visual>
            <visual>
				<origin rpy="0 0 0" xyz="0 0 0" />
				<geometry>
					<mesh filename="file:///$(find my_doosan_pkg)/description/meshes/a0912_blue/A0912_4_1.dae" scale="0.001 0.001 0.001" />
				</geometry>
			</visual>
		</link>


		<!-- joint5 -->
		<joint name="joint5" type="revolute">
			<parent link="link4" />
			<child link="link5" />
			<origin rpy="-1.571 0 0" xyz="0 0 0" />
			<axis xyz="0 0 1" />
			<limit effort="50" lower="-6.2832" upper="6.2832" velocity="6.2832"/>
			<dynamics damping="10.0" friction="1.0" />
		</joint>


		<!-- Link 5 -->
		<link name="link5">
			<inertial>
				<mass value="2.141"/>
				<origin xyz="0.000109   -0.003286     0.01477"/>
				<inertia ixx="0.013145" ixy="-4.7132e-06" ixz="8.5804e-06" iyy="0.0073072"
					iyz="-5.999e-05"
					izz="0.0090476"/>
			</inertial>
            <collision>
                <origin rpy="1.571 0 0" xyz="0 0 0" />
                <geometry>
                    <cylinder radius="0.06" length="0.15"/>
                </geometry>
            </collision>
			<visual>
				<origin rpy="0 0 0" xyz="0 0 0" />
				<geometry>
					<mesh filename="file:///$(find my_doosan_pkg)/description/meshes/a0912_blue/A0912_5_0.dae" scale="0.001 0.001 0.001" />
				</geometry>
			</visual>
            <visual>
				<origin rpy="0 0 0" xyz="0 0 0" />
				<geometry>
					<mesh filename="file:///$(find my_doosan_pkg)/description/meshes/a0912_blue/A0912_5_1.dae" scale="0.001 0.001 0.001" />
				</geometry>
			</visual>
		</link>


		<!-- joint6 -->
		<joint name="joint6" type="revolute">
			<parent link="link5" />
			<child link="link6" />
			<origin rpy="1.571 0 0" xyz="0 -0.124 0" />
			<axis xyz="0 0 1" />
			<limit effort="50" lower="-6.2832" upper="6.2832" velocity="6.2832"/>
			<dynamics damping="10.0" friction="1.0" />
		</joint>


		<!-- Link 6 -->
		<link name="link6">
			<inertial>
				<mass value="0.784"/>
				<origin xyz="-1.9e-05      -6e-06    -0.05227"/>
				<inertia ixx="0.0067403" ixy="5.2373e-06" ixz="2.4957e-06" iyy="0.0048015"
					iyz="8.3671e-06"
					izz="0.0059696"/>
			</inertial>
			<visual>
				<origin rpy="0 0 0" xyz="0 0 0" />
				<geometry>
					<mesh filename="file:///$(find my_doosan_pkg)/description/meshes/a0912_blue/A0912_6_0.dae" scale="0.001 0.001 0.001" />
				</geometry>
			</visual>
			<collision>
        		<geometry>
          			<mesh filename="file:///$(find my_doosan_pkg)/description/meshes/a0912_blue/A0912_6_0.dae" scale="0.001 0.001 0.001" />
        		</geometry>
      		</collision>
		</link>


		<!-- the following lines instantiates all the info described in the file macro.gazebo_config_control.xacro, transmissions and internal_config by david-->
		<xacro:config_ctr_gazebo /> 
		<xacro:dsr_transmission />
		<xacro:dsr_config_coeff /> 


	</xacro:macro>
</robot>
